<?xml version="1.0" encoding="UTF-8"?>
<testsuite name="test_get_open_door_tests.TestAccessManager-20210519173011" tests="1" file="test_get_open_door_tests.py" time="0.000" timestamp="2021-05-19T17:30:11" failures="1" errors="0" skipped="0">
	<testcase classname="test_get_open_door_tests.TestAccessManager" name="test_parametrized_cases_tests" time="0.000" timestamp="2021-05-19T17:30:11">
		<failure type="AssertionError" message="unexpectedly None"><![CDATA[Traceback (most recent call last):
  File "C:\Python38\lib\unittest\case.py", line 60, in testPartExecutor
    yield
  File "C:\Python38\lib\unittest\case.py", line 676, in run
    self._callTestMethod(testMethod)
  File "C:\Python38\lib\unittest\case.py", line 633, in _callTestMethod
    method()
  File "c:\users\aulavirtual\pycharmprojects\g81.t10.fp\src\unittest\python\test_get_open_door_tests.py", line 45, in test_parametrized_cases_tests
    self.assertIsNotNone(generated_key)
  File "C:\Python38\lib\unittest\case.py", line 1328, in assertIsNotNone
    self.fail(self._formatMessage(msg, standardMsg))
  File "C:\Python38\lib\unittest\case.py", line 753, in fail
    raise self.failureException(msg)
AssertionError: unexpectedly None
]]></failure>
	</testcase>
</testsuite>
